(dp1
S'output'
p2
S'<type \'exceptions.ValueError\'> Variable rnnlm/softmax_w already exists, disallowed. Did you mean to set reuse=True in VarScope? Originally defined at:\n\n  File "applications/draft/modules/model.py", line 32, in __init__\n    softmax_w = tf.get_variable("softmax_w", [args.rnn_size, args.vocab_size])\n  File "applications/draft/modules/sample.py", line 34, in sample\n    chars, vocab = cPickle.load(f)\n  File "applications/draft/modules/sample.py", line 27, in main\n    return(sample(args))\n'
p3
sS'layer'
p4
S'/home/ignii/web2py/applications/draft/controllers/test1.py'
p5
sS'code'
p6
S'# -*- coding: utf-8 -*-\n# try something like\nfrom sample import main\ndef myfunc():\n    return locals()\n\ndef runcode():\n    name = request.vars.ff\n    return locals()\n\ndef check():\n    print "ffff"\n    a=main()\n    # c=apb(4)\n    return a\n\nresponse._vars=response._caller(check)\n'
p7
sS'snapshot'
p8
(dp9
sS'traceback'
p10
S'Traceback (most recent call last):\n  File "/home/ignii/web2py/gluon/restricted.py", line 227, in restricted\n    exec ccode in environment\n  File "/home/ignii/web2py/applications/draft/controllers/test1.py", line 17, in <module>\n  File "/home/ignii/web2py/gluon/globals.py", line 417, in <lambda>\n    self._caller = lambda f: f()\n  File "/home/ignii/web2py/applications/draft/controllers/test1.py", line 13, in check\n    a=main()\n  File "applications/draft/modules/sample.py", line 27, in main\n    return(sample(args))\n  File "applications/draft/modules/sample.py", line 35, in sample\n    model = Model(saved_args, True)\n  File "applications/draft/modules/model.py", line 32, in __init__\n    softmax_w = tf.get_variable("softmax_w", [args.rnn_size, args.vocab_size])\n  File "/usr/local/lib/python2.7/dist-packages/tensorflow/python/ops/variable_scope.py", line 1024, in get_variable\n    custom_getter=custom_getter)\n  File "/usr/local/lib/python2.7/dist-packages/tensorflow/python/ops/variable_scope.py", line 850, in get_variable\n    custom_getter=custom_getter)\n  File "/usr/local/lib/python2.7/dist-packages/tensorflow/python/ops/variable_scope.py", line 346, in get_variable\n    validate_shape=validate_shape)\n  File "/usr/local/lib/python2.7/dist-packages/tensorflow/python/ops/variable_scope.py", line 331, in _true_getter\n    caching_device=caching_device, validate_shape=validate_shape)\n  File "/usr/local/lib/python2.7/dist-packages/tensorflow/python/ops/variable_scope.py", line 632, in _get_single_variable\n    name, "".join(traceback.format_list(tb))))\nValueError: Variable rnnlm/softmax_w already exists, disallowed. Did you mean to set reuse=True in VarScope? Originally defined at:\n\n  File "applications/draft/modules/model.py", line 32, in __init__\n    softmax_w = tf.get_variable("softmax_w", [args.rnn_size, args.vocab_size])\n  File "applications/draft/modules/sample.py", line 34, in sample\n    chars, vocab = cPickle.load(f)\n  File "applications/draft/modules/sample.py", line 27, in main\n    return(sample(args))\n\n'
p11
s.